<?xml version="1.0" ?>
<sdf version="1.10">


    <!--this section of the code defines the 3D space the objects will lie in-->
    <world name="robot_world">
        <physics name="1ms" type="ignored">
            <max_step_size>0.001</max_step_size>
            <real_time_factor>1.0</real_time_factor>
        </physics>
        <plugin
            filename="gz-sim-physics-system"
            name="gz::sim::systems::Physics">
        </plugin>
        <plugin
            filename="gz-sim-user-commands-system"
            name="gz::sim::systems::UserCommands">
        </plugin>
        <plugin
            filename="gz-sim-scene-broadcaster-system"
            name="gz::sim::systems::SceneBroadcaster">
        </plugin>

        <light type="directional" name="sun">
            <cast_shadows>true</cast_shadows>
            <pose>0 0 10 0 0 0</pose>
            <diffuse>0.8 0.8 0.8 1</diffuse>
            <specular>0.2 0.2 0.2 1</specular>
            <attenuation>
                <range>1000</range>
                <constant>0.9</constant>
                <linear>0.01</linear>
                <quadratic>0.001</quadratic>
            </attenuation>
            <direction>-0.5 0.1 -0.9</direction>
        </light>


        <!--This section defines the ground of the world-->
        <model name="ground_plane">
            <static>true</static>
            <link name="link">
                <collision name="collision">
                <geometry>
                    <plane>
                    <normal>0 0 1</normal>
                    </plane>
                </geometry>
                </collision>
                <visual name="visual">
                <geometry>
                    <plane>
                    <normal>0 0 1</normal>
                    <size>100 100</size>
                    </plane>
                </geometry>
                <material>
                    <ambient>0.8 0.8 0.8 1</ambient>
                    <diffuse>0.8 0.8 0.8 1</diffuse>
                    <specular>0.8 0.8 0.8 1</specular>
                </material>
                </visual>
            </link>
        </model>

        <!--Model of legs-->
        <model name='neptr' conical_link='chassis'>
            <pose relative_to='world'>0 0 0 0 0 0</pose> <!--x y z r p y-->
            
            <link name='foot'>
                <pose relative_to='__model__'>0 0 0 0 0 0</model>
                <inertial>
                    <mass>1</mass>
                    <inertia>
                        <ixx>0.095329</ixx>
                        <ixy>0</ixy>
                        <ixz>0</ixz>
                        <iyy>0.381317</iyy>
                        <iyz>0</iyz>
                        <izz>0.476646</izz>
                    </inertia>
                </inertial>
                <visual>
                    <geometry>
                        <box>
                            <size>2 1 .5</size>
                        </box>
                    </geometry>
                    <material>
                        <ambient>0.0 0.0 1.0 1</ambient>
                        <diffuse>0.0 0.0 1.0 1</diffuse>
                        <specular>0.0 0.0 1.0 1</specular>
                    </material>
                </visual>
                <collision>
                    <geometry>
                        <box>
                            <size>3 2 1</size>
                        </box>
                    </geometry>
                </collision>
            </link>

            <link name='ankle'>
                <pose relative_to='foot'> -2.5 0 0 0 -1.5707 0</pose> <!---1.5707 is 90 degrees and turns crlinder on its side-->
                <inertial>
                    <mass>1</mass>
                    <inertia>
                        <ixx>0.095329</ixx>
                        <ixy>0</ixy>
                        <ixz>0</ixz>
                        <iyy>0.381317</iyy>
                        <iyz>0</iyz>
                        <izz>0.476646</izz>
                    </inertia>
                </inertial>
                <visual>
                    <geometry>
                        <cyllinder>
                            <radius>0.5</radius>
                            <length>1.0</length> <!--spans the y lengt of foot-->
                        </cyllinder>
                    </geometry>
                    <material>
                        <ambient>0.0 0.0 1.0 1</ambient>
                        <diffuse>0.0 0.0 1.0 1</diffuse>
                        <specular>0.0 0.0 1.0 1</specular>
                    </material>
                </visual>
                <collision>
                    <geometry>
                        <cyllinder>
                            <radius>0.5</radius>
                            <length>1.0</length> <!--spans the y lengt of foot-->
                        </cyllinder>
                    </geometry>
                </collision>
            </link>

            <link name='calf'>
                <pose relative_to='ankle'>0 1 0 0 0 0</pose>
                <inertial>
                    <mass>1</mass>
                    <inertia>
                        <ixx>0.095329</ixx>
                        <ixy>0</ixy>
                        <ixz>0</ixz>
                        <iyy>0.381317</iyy>
                        <iyz>0</iyz>
                        <izz>0.476646</izz>
                    </inertia>
                </inertial>
                <visual>
                    <geometry>
                        <box>
                            <size>2 1 .5</size>
                        </box>
                    </geometry>
                    <material>
                        <ambient>0.0 0.0 1.0 1</ambient>
                        <diffuse>0.0 0.0 1.0 1</diffuse>
                        <specular>0.0 0.0 1.0 1</specular>
                    </material>
                </visual>
                <collision>
                    <geometry>
                        <box>
                            <size>3 2 1</size>
                        </box>
                    </geometry>
                </collision>
            </link>

            <!--implement the rest of the leg-->

            <joint name='foot_ankle_joint' type='revolute'>
                <pose relative_to='foot'/>
                <parent>ankle</parent>
                <child>foot</child>
                 <axis>
                    <xyz expressed_in='__model__'>0 1 0</xyz> <!--can be defined as any frame or even arbitrary frames-->
                    <limit>
                        <lower>-1.79769e+308</lower>    <!--negative infinity-->
                        <upper>1.79769e+308</upper>     <!--positive infinity-->
                    </limit>
                </axis>
            </joint>

            <!--figure out how to join calk to ankle rotation point-->
        </model>
    </world>
</sdf>
