<?xml version="1.0" ?>
<!-- =================================================================================== -->
<!-- |    This document was autogenerated by xacro from /home/ab1119043/ros2_ws/src/neptr_description/urdf/neptr.urdf.xacro | -->
<!-- |    EDITING THIS FILE BY HAND IS NOT RECOMMENDED                                 | -->
<!-- =================================================================================== -->
<robot name="neptr">
  <!-- Root Link -->
  <link name="world"/>
  <!-- Base Link -->
  <link name="base_link">
    <visual>
      <origin rpy="0 0 0" xyz="0 0 0"/>
      <geometry>
        <box size="0.2 0.2 0.1"/>
      </geometry>
      <material name="blue">
        <color rgba="0 0 1 1"/>
      </material>
    </visual>
  </link>
  <!-- Fixed Joint to World -->
  <joint name="world_to_base" type="fixed">
    <parent link="world"/>
    <child link="base_link"/>
    <origin rpy="0 0 0" xyz="0 0 0"/>
  </joint>
  <!-- Thigh -->
  <link name="thigh">
    <visual>
      <origin rpy="0 0 0" xyz="0 -0.125 0"/>
      <geometry>
        <box size="0.05 0.25 0.05"/>
      </geometry>
      <material name="red">
        <color rgba="1 0 0 1"/>
      </material>
    </visual>
  </link>
  <!-- Hip Joint -->
  <joint name="hip_joint" type="revolute">
    <parent link="base_link"/>
    <child link="thigh"/>
    <origin rpy="0 0 0" xyz="0 0 -0.05"/>
    <axis xyz="0 1 0"/>
    <limit effort="10" lower="-1.57" upper="1.57" velocity="2"/>
  </joint>
  <!-- Shin -->
  <link name="shin">
    <visual>
      <origin rpy="0 0 0" xyz="0 -0.125 0"/>
      <geometry>
        <box size="0.05 0.25 0.05"/>
      </geometry>
      <material name="green">
        <color rgba="0 1 0 1"/>
      </material>
    </visual>
  </link>
  <!-- Knee Joint -->
  <joint name="knee_joint" type="revolute">
    <parent link="thigh"/>
    <child link="shin"/>
    <origin rpy="0 0 0" xyz="0 -0.25 0"/>
    <axis xyz="0 1 0"/>
    <limit effort="10" lower="0" upper="2.5" velocity="2"/>
  </joint>
  <!-- Foot -->
  <link name="foot">
    <visual>
      <origin rpy="0 0 0" xyz="0 -0.05 0"/>
      <geometry>
        <box size="0.15 0.05 0.1"/>
      </geometry>
      <material name="yellow">
        <color rgba="1 1 0 1"/>
      </material>
    </visual>
  </link>
  <!-- Ankle Joint -->
  <joint name="ankle_joint" type="revolute">
    <parent link="shin"/>
    <child link="foot"/>
    <origin rpy="0 0 0" xyz="0 -0.25 0"/>
    <axis xyz="1 0 0"/>
    <limit effort="10" lower="-1.57" upper="1.57" velocity="2"/>
  </joint>
</robot>
