<robot xmlns:xacro="http://ros.org/wiki/xacro" name="biped_leg">
  <!-- Root Link -->
  <link name="world"/>

  <!-- Base Link -->
  <link name="base_link">
    <visual>
      <origin xyz="0 0 1" rpy="0 0 0"/>
      <geometry>
        <box size="0.2 0.2 0.1"/>
      </geometry>
      <material name="blue">
        <color rgba="0 0 1 1"/>
      </material>
    </visual>
  </link>

  <!-- Fixed Joint to World -->
  <joint name="world_to_base" type="fixed">
    <parent link="world"/>
    <child link="base_link"/>
    <origin xyz="0 0 1" rpy="0 0 0"/>
  </joint>

  <!-- Thigh -->
  <link name="thigh">
    <visual>
      <origin xyz="0 0 0.25" rpy="0 0 0"/>
      <geometry>
        <box size="0.05 0.5 0.05"/>
      </geometry>
      <material name="red">
        <color rgba="1 0 0 1"/>
      </material>
    </visual>
  </link>

  <!-- Hip Joint -->
  <joint name="hip_joint" type="revolute">
    <parent link="base_link"/>
    <child link="thigh"/>
    <origin xyz="0 .1 .1" rpy="1.57 0.785 0"/>
    <axis xyz="0 1 0"/>
    <limit effort="10" velocity="2" lower="-1.57" upper="1.57"/>
  </joint>

  <!-- Shin -->
  <link name="shin">
    <visual>
      <origin xyz="0 0 -0.25" rpy="0 0 0"/>
      <geometry>
        <box size="0.05 0.5 0.05"/>
      </geometry>
      <material name="green">
        <color rgba="0 1 0 1"/>
      </material>
    </visual>
  </link>

  <!-- Knee Joint -->
  <joint name="knee_joint" type="revolute">
    <parent link="thigh"/>
    <child link="shin"/>
    <origin xyz="0 0 -0.5" rpy="0 0 0"/>
    <axis xyz="0 1 0"/>
    <limit effort="10" velocity="2" lower="0" upper="2.5"/>
  </joint>

  <!-- Foot -->
  <link name="foot">
    <visual>
      <origin xyz="0 0 -0.025" rpy="0 0 0"/>
      <geometry>
        <box size="0.15 0.05 0.05"/>
      </geometry>
      <material name="yellow">
        <color rgba="1 1 0 1"/>
      </material>
    </visual>
  </link>

  <!-- Ankle Joint -->
  <joint name="ankle_joint" type="revolute">
    <parent link="shin"/>
    <child link="foot"/>
    <origin xyz="0 0 -0.5" rpy="0 0 0"/>
    <axis xyz="1 0 0"/>
    <limit effort="10" velocity="2" lower="-1.57" upper="1.57"/>
  </joint>
</robot>


  <!-- Root Link
  <link name="world"/>

  Base Link
  <link name="base_link">
    <visual>
      <origin xyz="0 0 0" rpy="0 0 0"/>
      <geometry>
        <cylinder length="0.6" radius="0.2"/>
      </geometry>
      <material name="blue">
        <color rgba="0 0 1 1"/>
      </material>
    </visual>
  </link>

  Fixed Joint to World
  <joint name="world_to_base" type="fixed">
    <parent link="world"/>
    <child link="base_link"/>
    <origin xyz="0 0 0" rpy="0 0 0"/>
  </joint>

  Thigh
  <link name="thigh">
    <visual>
      <origin xyz="0 0 -0.125" rpy="0 0 0"/>
      <geometry>
        <box size="0.05 0.25 0.05"/>
      </geometry>
      <material name="red">
        <color rgba="1 0 0 1"/>
      </material>
    </visual>
  </link>

  Hip Joint
  <joint name="hip_joint" type="revolute">
    <parent link="base_link"/>
    <child link="thigh"/>
    <origin xyz="0 0 -0.05" rpy="0 0 0"/>
    <axis xyz="0 1 0"/>
    <limit effort="10" velocity="2" lower="-1.57" upper="1.57"/>
  </joint>

  Shin
  <link name="shin">
    <visual>
      <origin xyz="0 0 -0.125" rpy="0 0 0"/>
      <geometry>
        <box size="0.05 0.25 0.05"/>
      </geometry>
      <material name="green">
        <color rgba="0 1 0 1"/>
      </material>
    </visual>
  </link>

  Knee Joint
  <joint name="knee_joint" type="revolute">
    <parent link="thigh"/>
    <child link="shin"/>
    <origin xyz="0 0 -0.25" rpy="0 0 0"/>
    <axis xyz="0 1 0"/>
    <limit effort="10" velocity="2" lower="0" upper="2.5"/>
  </joint>

  Foot
  <link name="foot">
    <visual>
      <origin xyz="0 0 -0.025" rpy="0 0 0"/>
      <geometry>
        <box size="0.1 0.05 0.02"/>
      </geometry>
      <material name="yellow">
        <color rgba="1 1 0 1"/>
      </material>
    </visual>
  </link>

  Ankle Joint
  <joint name="ankle_joint" type="revolute">
    <parent link="shin"/>
    <child link="foot"/>
    <origin xyz="0 0 -0.25" rpy="0 0 0"/>
    <axis xyz="0 1 0"/>
    <limit effort="10" velocity="2" lower="-1.57" upper="1.57"/>
  </joint>

  Camera
  <link name="camera">
    <visual>
      <origin xyz="0 0 -0.2"/>
      <geometry>
        <box size="0.2 0.2 0.4"/>
      </geometry>
      <material name="blue">
        <color rgba="0 0 1 1"/>
      </material>
    </visual>
  </link>

  Fixed Camera Joint
  <joint name="world_to_camera" type="fixed">
    <parent link="world"/>
    <child link="camera"/>
    <origin xyz="4 1 2" rpy="-2 0 2.5"/>
  </joint>

</robot> -->


